Workbook
Name MMI: Tabelas!$A$49:$F$53

Sheet Dashboard
A1: BJJ PERFORMANCE
B6: Inicio | C6: 46041 | E6: Name | F6: EMANOEL MACEDO | Q6: Gênero | S6: Masculino
B9: DADOS DE LUTA - Treinamento Aeróbico
B12: Duração da luta (min) | D12: 5
B13: Média de lutas em campeonato | D13: 4
B16: COMPOSIÇÃO CORPORAL
B19: Date | D19: 46041
B20: Idade | D20: 20
B21: Estatura (cm) | D21: 165
B22: Massa corporal (Kg) | D22: 80
B23: Perimetria Pescoço (cm) | D23: 40
B24: Perimetria Abdomen (cm) | D24: 75
B25: Perimetria Quadril (cm)
B26: Gordura (%) | D26: =IF(S6 = "Masculino", 495/(1.034-0.19077*LOG10(D24-D23)+0.1546*LOG10(D21))-450, 495/(1.29579 - 0.35004*LOG10(D24+D25-D23) + 0.221*LOG10(D21)) - 450) -> 7.3757423 | E26: {=495/(1.034-0.19077*LOG10(E24-E23)+0.1546*LOG10(E21))-450} -> #NUM!
B27: Gordura (Kg) | D27: {=(D26*D22)/100} -> 5.9005938 | E27: {=(E26*E22)/100} -> #NUM!
B28: Massa Livre de Gordura (Kg) | D28: {=D22-D27} -> 74.099406 | E28: {=E22-E27} -> #NUM!
B31: BOLETIM
L34: VO2 máx | O34: Percentual de Gordura | R34: Força
L35: ='Semana de Reteste'!G24 -> -1 | O35: =(E26-D26)/-D26 -> #NUM! | R35: =(SUM(I41:I44)-SUM(G41:G44))/SUM(G41:G44) -> #DIV/0!
B38: O quão forte você está com 1 número
B40: Que força estamos avaliando ? | D40: qual exercício esta usando ? | F40: 1RM (Kg) Inicial | G40: Força Relativa | H40: 1RM (Kg) Final | I40: Força Relativa
B41: Membros Superiores Puxada | D41: ='Semana de Teste'!E12 -> Remada Inclinada ( Barbell Row ) | F41: ='Semana de Teste'!O12 -> 0 | G41: =F41/$D$22 -> 0 | H41: ='Semana de Reteste'!S12 -> 0 | I41: =H41/$E$22 -> #DIV/0!
B42: Membros Superiores Empurrda | D42: ='Semana de Teste'!E7 -> Supino Reto ( Bench Press ) | F42: ='Semana de Teste'!O7 -> 90.656 | G42: =F42/$D$22 -> 1.1332 | H42: ='Semana de Reteste'!S7 -> 118.7892 | I42: =H42/$E$22 -> #DIV/0!
B43: Membros Inferiores Empurrada | D43: ='Semana de Teste'!E17 -> Agachamento com Barra nas Costas (Back Squat) | F43: ='Semana de Teste'!O17 -> 0 | G43: =F43/$D$22 -> 0 | H43: ='Semana de Reteste'!S17 -> 0 | I43: =H43/$E$22 -> #DIV/0!
B44: Membros Inferiores Puxada | D44: ='Semana de Teste'!E18 -> Levantamento Terra ( Deadlift) | F44: ='Semana de Teste'!O18 -> 0 | G44: =F44/$D$22 -> 0 | H44: ='Semana de Reteste'!S18 -> 0 | I44: =H44/$E$22 -> #DIV/0!
L55: =D41 -> Remada Inclinada ( Barbell Row ) | N55: =D42 -> Supino Reto ( Bench Press ) | P55: =D43 -> Agachamento com Barra nas Costas (Back Squat) | R55: =D44 -> Levantamento Terra ( Deadlift)
L56: =IF(F41=0,"Realize a Semana Teste", IF(I41=0, "Aguardando Teste Final",(I41-G41)/G41)) -> Realize a Semana Teste | N56: =IF(F42=0,"Realize a Semana Teste",IF(I42 = 0, "Aguardando Teste Final", (I42 - G42) / G42)) -> #DIV/0! | P56: =IF(F41=0,"Realize a Semana Teste",IF(I43 = 0, "Aguardando Teste Final", (I43-G43)/G43)) -> Realize a Semana Teste | R56: =IF(F41=0,"Realize a Semana Teste",IF(I44 = 0, "Aguardando Teste Final", (I44-G44)/G44)) -> Realize a Semana Teste
B61: MONITORAMENTO DO TREINAMENTO - GAMEFICAÇÃO
L64: Presença Geral | O64: =SUM(O66:R66)/4 -> 0
L65: Presença | O65: 1 | P65: 2 | Q65: 3 | R65: 4
O66: =Treinamento!N3/Treinamento!M3 -> 0 | P66: =Treinamento!N5/Treinamento!M5 -> 0 | Q66: =Treinamento!N7/Treinamento!M7 -> 0 | R66: =Treinamento!N9/Treinamento!M9 -> 0
L69: Aproveitamento do Treinamento
L71: Semanas | M71: 1 | N71: 2 | O71: 3 | P71: 4
L72: Upper Body Push | M72: =Treinamento!E6 -> 0.14666667 | N72: =Treinamento!F6 -> 0 | O72: =Treinamento!G6 -> 0 | P72: =Treinamento!H6 -> 0
L73: Upper Body Pull | M73: =Treinamento!E7 -> 0 | N73: =Treinamento!F7 -> 0 | O73: =Treinamento!G7 -> 0 | P73: =Treinamento!H7 -> 0
L74: Lower Body | M74: =Treinamento!E8 -> 0 | N74: =Treinamento!F8 -> 0 | O74: =Treinamento!G8 -> 0 | P74: =Treinamento!H8 -> 0
M75: =Treinamento!E9 | N75: =Treinamento!F9 | O75: =Treinamento!G9 | P75: =Treinamento!H9
L76: Microciclo | M76: =Treinamento!E10 -> 0.048888889 | N76: =Treinamento!F10 -> 0 | O76: =Treinamento!G10 -> 0 | P76: =Treinamento!H10 -> 0
L77: Meta | M77: 0.8 | N77: 0.8 | O77: 0.8 | P77: 0.8

Sheet Semana de Teste
C2: TESTE | Q2: Segunda | R2: Terça | S2: Quarta | T2: Quinta | U2: Sexta | V2: Sábado | W2: Domingo
Q3: Empurrada | R3: Vo2 max | S3: Membros Inferiores | T3: Descanso | U3: Puxada | V3: Aula | W3: Descanso
C5: Treino | D5: N | E5: Exercício | F5: Série 1 | I5: Série 2 | L5: Série 3 | O5: 1 RM
F6: Carga | G6: Repetições | H6: Descanso | I6: Carga | J6: Repetições | K6: Descanso | L6: Carga | M6: Repetições | N6: Descanso
C7: Membros Superiores Empurrada | D7: 1 | E7: Supino Reto ( Bench Press ) | F7: 70 | G7: 5 | H7: 3 minutos | I7: 80 | J7: 3 | K7: 3 minutos | L7: 80 | M7: 4 | N7: 3 minutos | O7: =IF(M7=1,L7,(M7*L7*0.0333)+L7) -> 90.656
D8: 2 | E8: Supino Inclinado com Barra | H8: 3 minutos | K8: 3 minutos | N8: 3 minutos | O8: =IF(M8=1,L8,(M8*L8*0.0333)+L8) -> 0
D9: 3 | E9: Dumbbell Shoulder Press | H9: 3 minutos | K9: 3 minutos | N9: 3 minutos | O9: =IF(M9=1,L9,(M9*L9*0.0333)+L9) -> 0
D10: 4 | E10: Remada Alta com Barra | H10: 3 minutos | K10: 3 minutos | N10: 3 minutos | O10: =IF(M10=1,L10,(M10*L10*0.0333)+L10) -> 0
D11: 5 | E11: Tríceps Pulley | H11: 3 minutos | K11: 3 minutos | N11: 3 minutos | O11: =IF(M11=1,L11,(M11*L11*0.0333)+L11) -> 0
C12: Membros Superiores Puxada | D12: 1 | E12: Remada Inclinada ( Barbell Row ) | H12: 3 minutos | K12: 3 minutos | N12: 3 minutos | O12: =IF(M12=1,L12,(M12*L12*0.0333)+L12) -> 0
D13: 2 | E13: Puxada Frontal ( Supinação ) | H13: 3 minutos | K13: 3 minutos | N13: 3 minutos | O13: =IF(M13=1,L13,(M13*L13*0.0333)+L13) -> 0
D14: 3 | E14: Remada Inclinada com Halter | H14: 3 minutos | K14: 3 minutos | N14: 3 minutos | O14: =IF(M14=1,L14,(M14*L14*0.0333)+L14) -> 0
D15: 4 | E15: Voador Inverso no banco inclinado com Halter | H15: 3 minutos | K15: 3 minutos | N15: 3 minutos | O15: =IF(M15=1,L15,(M15*L15*0.0333)+L15) -> 0
D16: 5 | E16: Rosca Martelo com Halter | H16: 3 minutos | K16: 3 minutos | N16: 3 minutos | O16: =IF(M16=1,L16,(M16*L16*0.0333)+L16) -> 0
C17: Membros Inferiores | D17: 1 | E17: Agachamento com Barra nas Costas (Back Squat) | H17: 3 minutos | K17: 3 minutos | N17: 3 minutos | O17: =IF(M17=1,L17,(M17*L17*0.0333)+L17) -> 0
D18: 2 | E18: Levantamento Terra ( Deadlift) | H18: 3 minutos | K18: 3 minutos | N18: 3 minutos | O18: =IF(M18=1,L18,(M18*L18*0.0333)+L18) -> 0
D19: 3 | E19: Afundo com Halteres | H19: 3 minutos | K19: 3 minutos | N19: 3 minutos | O19: =IF(M19=1,L19,(M19*L19*0.0333)+L19) -> 0
D20: 4 | E20: Stiff com Halter | H20: 3 minutos | K20: 3 minutos | N20: 3 minutos | O20: =IF(M20=1,L20,(M20*L20*0.0333)+L20) -> 0
C23: Distance 12 min | D23: 2600 | G23: Objetivos dos Teste de Força -na ultima tentativa chegar na maior carga entre 3 a 5 repetições. Objetivo do teste Vo2 Max Maior distancia em metros em 12 minutos com a esteira a 1% de inclinação.
C24: Vo2max (ml/kg/min) | D24: =((D23-504.1)/44.9) -> 46.679287
C25: Vvo2 max (km/h) | D25: =((D23/ 12)*0.06) -> 13

Sheet Treinamento
Q1: Segunda | R1: Terça | S1: Quarta | T1: Quinta | U1: Sexta | V1: Sábado | W1: Domingo
Q2: Empurrada | R2: Aeróbico | S2: Membros Inferiroes | T2: Descanso | U2: Puxada | V2: Aeróbico | W2: Descanso
D3: Aproveitamento do Treinamento | M3: 5 | N3: =COUNTIF(Q3:W3,TRUE) -> 0 | P3: 1 | Q3: FALSE | R3: FALSE | S3: FALSE | U3: FALSE | V3: FALSE
Q4: =Dashboard!C6 -> 46041 | R4: =Q4+1 -> 46042 | S4: =R4+1 -> 46043 | T4: =S4+1 -> 46044 | U4: =T4+1 -> 46045 | V4: =U4+1 -> 46046 | W4: =V4+1 -> 46047
D5: Semana | E5: 1 | F5: 2 | G5: 3 | H5: 4 | M5: 5 | N5: =COUNTIF(Q5:W5,TRUE) -> 0 | P5: 2 | Q5: FALSE | R5: FALSE | S5: FALSE | U5: FALSE | V5: FALSE
D6: Upper Body Push | E6: =AVERAGE(O13:O17) -> 0.14666667 | F6: =AVERAGE(O28:O32) -> 0 | G6: =AVERAGE(O43:O47) -> 0 | H6: =AVERAGE(O58:O62) -> 0 | Q6: =W4+1 -> 46048 | R6: =Q6+1 -> 46049 | S6: =R6+1 -> 46050 | T6: =S6+1 -> 46051 | U6: =T6+1 -> 46052 | V6: =U6+1 -> 46053 | W6: =V6+1 -> 46054
D7: Upper Body Pull | E7: =AVERAGE(O18:O22) -> 0 | F7: =AVERAGE(O33:O37) -> 0 | G7: =AVERAGE(O48:O52) -> 0 | H7: =AVERAGE(O63:O67) -> 0 | M7: 5 | N7: =COUNTIF(Q7:W7,TRUE) -> 0 | P7: 3 | Q7: FALSE | R7: FALSE | S7: FALSE | U7: FALSE | V7: FALSE
D8: Lower Body | E8: =AVERAGE(O23:O26) -> 0 | F8: =AVERAGE(O38:O41) -> 0 | G8: =AVERAGE(O53:O56) -> 0 | H8: =AVERAGE(O68:O71) -> 0 | Q8: =W6+1 -> 46055 | R8: =Q8+1 -> 46056 | S8: =R8+1 -> 46057 | T8: =S8+1 -> 46058 | U8: =T8+1 -> 46059 | V8: =U8+1 -> 46060 | W8: =V8+1 -> 46061
M9: 5 | N9: =COUNTIF(Q9:W9,TRUE) -> 0 | P9: 4 | Q9: FALSE | R9: FALSE | S9: FALSE | U9: FALSE | V9: FALSE
D10: Microciclo | E10: =AVERAGE(E6:E8) -> 0.048888889 | F10: =AVERAGE(F6:F8) -> 0 | G10: =AVERAGE(G6:G8) -> 0 | H10: =AVERAGE(H6:H8) -> 0 | Q10: =W8+1 -> 46062 | R10: =Q10+1 -> 46063 | S10: =R10+1 -> 46064 | T10: =S10+1 -> 46065 | U10: =T10+1 -> 46066 | V10: =U10+1 -> 46067 | W10: =V10+1 -> 46068
D12: Semana | E12: Treino | G12: Exercício | H12: Intensidade | I12: Carga (Kg) | J12: Reps | K12: Descanso | L12: Set 1 | M12: Set 2 | N12: Set 3 | O12: Exercício | P12: Semana
D13: 1 | E13: Mebros Superiores Empurrada | F13: 1 | G13: ='Semana de Teste'!E7 -> Supino Reto ( Bench Press ) | H13: 0.6 | I13: {=H13*'Semana de Teste'!$O$7} -> 54.3936 | J13: 20 | K13: 0.0010416667 | L13: 20 | M13: 13 | N13: 11 | O13: {=SUM(L13:N13)/(J13*3)} -> 0.73333333 | P13: =AVERAGE(O13:O26) -> 0.052380952 | R13: Semana | S13: Treino | T13: Séries | U13: Duração (min) | V13: Intensidade | W13: Km/h | X13: Distancia | Y13: PSE | Z13: Média da FC (bpm)
G14: ='Semana de Teste'!E8 -> Supino Inclinado com Barra | H14: 0.6 | I14: {=H14*'Semana de Teste'!$O$8} -> 0 | J14: 20 | K14: 0.0010416667 | O14: {=SUM(L14:N14)/(J14*3)} -> 0 | R14: 1 | S14: 1 | T14: 1 | U14: =Dashboard!$D$12*Dashboard!$D$13 -> 20 | V14: 0.6 | W14: =V14*'Semana de Teste'!$D$25 -> 7.8 | Y14: -
G15: ='Semana de Teste'!E9 -> Dumbbell Shoulder Press | H15: 0.6 | I15: {=H15*'Semana de Teste'!$O$9} -> 0 | J15: 20 | K15: 0.0010416667 | O15: {=SUM(L15:N15)/(J15*3)} -> 0 | V15: 0.7 | W15: =V15*'Semana de Teste'!$D$25 -> 9.1
G16: ='Semana de Teste'!E10 -> Remada Alta com Barra | H16: 0.6 | I16: {=H16*'Semana de Teste'!$O$10} -> 0 | J16: 20 | K16: 0.0010416667 | O16: {=SUM(L16:N16)/(J16*3)} -> 0 | S16: 2 | T16: 1 | U16: =Dashboard!$D$12*Dashboard!$D$13 -> 20 | V16: 0.6 | W16: =V16*'Semana de Teste'!$D$25 -> 7.8 | Y16: -
G17: ='Semana de Teste'!E11 -> Tríceps Pulley | H17: 0.6 | I17: {=H17*'Semana de Teste'!$O$11} -> 0 | J17: 20 | K17: 0.0010416667 | O17: {=SUM(L17:N17)/(J17*3)} -> 0 | V17: 0.7 | W17: =V17*'Semana de Teste'!$D$25 -> 9.1
E18: Membros Superiores Puxada | F18: 2 | G18: ='Semana de Teste'!E12 -> Remada Inclinada ( Barbell Row ) | H18: 0.6 | I18: {=H18*'Semana de Teste'!$O$12} -> 0 | J18: 20 | K18: 0.0010416667 | O18: {=SUM(L18:N18)/(J18*3)} -> 0 | R18: 2 | S18: 3 | T18: 1 | U18: =Dashboard!$D$12*Dashboard!$D$13 -> 20 | V18: 0.6 | W18: =V18*'Semana de Teste'!$D$25 -> 7.8 | Y18: -
G19: ='Semana de Teste'!E13 -> Puxada Frontal ( Supinação ) | H19: 0.6 | I19: {=H19*'Semana de Teste'!$O$13} -> 0 | J19: 20 | K19: 0.0010416667 | O19: {=SUM(L19:N19)/(J19*3)} -> 0 | V19: 0.7 | W19: =V19*'Semana de Teste'!$D$25 -> 9.1
G20: ='Semana de Teste'!E14 -> Remada Inclinada com Halter | H20: 0.6 | I20: {=H20*'Semana de Teste'!$O$14} -> 0 | J20: 20 | K20: 0.0010416667 | O20: {=SUM(L20:N20)/(J20*3)} -> 0 | S20: 4 | T20: 1 | U20: =Dashboard!$D$12*Dashboard!$D$13 -> 20 | V20: 0.6 | W20: =V20*'Semana de Teste'!$D$25 -> 7.8 | Y20: -
G21: ='Semana de Teste'!E15 -> Voador Inverso no banco inclinado com Halter | H21: 0.6 | I21: {=H21*'Semana de Teste'!$O$15} -> 0 | J21: 20 | K21: 0.0010416667 | O21: {=SUM(L21:N21)/(J21*3)} -> 0 | V21: 0.7 | W21: =V21*'Semana de Teste'!$D$25 -> 9.1
G22: ='Semana de Teste'!E16 -> Rosca Martelo com Halter | H22: 0.6 | I22: {=H22*'Semana de Teste'!$O$16} -> 0 | J22: 20 | K22: 0.0010416667 | O22: {=SUM(L22:N22)/(J22*3)} -> 0 | R22: 3 | S22: 5 | T22: 1 | U22: =Dashboard!$D$12*Dashboard!$D$13 -> 20 | V22: 0.6 | W22: =V22*'Semana de Teste'!$D$25 -> 7.8 | Y22: -
E23: Membros Inferiores | F23: 3 | G23: ='Semana de Teste'!E17 -> Agachamento com Barra nas Costas (Back Squat) | H23: 0.6 | I23: {=H23*'Semana de Teste'!$O$17} -> 0 | J23: 20 | K23: 0.0010416667 | O23: {=SUM(L23:N23)/(J23*3)} -> 0 | V23: 0.7 | W23: =V23*'Semana de Teste'!$D$25 -> 9.1
G24: ='Semana de Teste'!E18 -> Levantamento Terra ( Deadlift) | H24: 0.6 | I24: {=H24*'Semana de Teste'!$O$18} -> 0 | J24: 20 | K24: 0.0010416667 | O24: {=SUM(L24:N24)/(J24*3)} -> 0 | S24: 6 | T24: 1 | U24: =Dashboard!$D$12*Dashboard!$D$13 -> 20 | V24: 0.6 | W24: =V24*'Semana de Teste'!$D$25 -> 7.8 | Y24: -
G25: ='Semana de Teste'!E19 -> Afundo com Halteres | H25: 0.6 | I25: {=H25*'Semana de Teste'!$O$19} -> 0 | J25: 20 | K25: 0.0010416667 | O25: {=SUM(L25:N25)/(J25*3)} -> 0 | V25: 0.7 | W25: =V25*'Semana de Teste'!$D$25 -> 9.1
G26: ='Semana de Teste'!E20 -> Stiff com Halter | H26: 0.6 | I26: {=H26*'Semana de Teste'!$O$20} -> 0 | J26: 20 | K26: 0.0010416667 | O26: {=SUM(L26:N26)/(J26*3)} -> 0 | R26: 4 | S26: 7 | T26: 1 | U26: =Dashboard!$D$12*Dashboard!$D$13 -> 20 | V26: 0.6 | W26: =V26*'Semana de Teste'!$D$25 -> 7.8 | Y26: -
V27: 0.7 | W27: =V27*'Semana de Teste'!$D$25 -> 9.1
D28: 2 | E28: Mebros Superiores Empurrada | F28: 4 | G28: ='Semana de Teste'!E7 -> Supino Reto ( Bench Press ) | H28: 0.6 | I28: {=H28*'Semana de Teste'!$O$7} -> 54.3936 | J28: 20 | K28: 0.0010416667 | O28: {=SUM(L28:N28)/(J28*3)} -> 0 | P28: =AVERAGE(O28:O41) -> 0 | S28: 8 | T28: 1 | U28: =Dashboard!$D$12*Dashboard!$D$13 -> 20 | V28: 0.6 | W28: =V28*'Semana de Teste'!$D$25 -> 7.8
G29: ='Semana de Teste'!E8 -> Supino Inclinado com Barra | H29: 0.6 | I29: {=H29*'Semana de Teste'!$O$8} -> 0 | J29: 20 | K29: 0.0010416667 | O29: {=SUM(L29:N29)/(J29*3)} -> 0 | V29: 0.7 | W29: =V29*'Semana de Teste'!$D$25 -> 9.1
G30: ='Semana de Teste'!E9 -> Dumbbell Shoulder Press | H30: 0.6 | I30: {=H30*'Semana de Teste'!$O$9} -> 0 | J30: 20 | K30: 0.0010416667 | O30: {=SUM(L30:N30)/(J30*3)} -> 0
G31: ='Semana de Teste'!E10 -> Remada Alta com Barra | H31: 0.6 | I31: {=H31*'Semana de Teste'!$O$10} -> 0 | J31: 20 | K31: 0.0010416667 | O31: {=SUM(L31:N31)/(J31*3)} -> 0
G32: ='Semana de Teste'!E11 -> Tríceps Pulley | H32: 0.6 | I32: {=H32*'Semana de Teste'!$O$11} -> 0 | J32: 20 | K32: 0.0010416667 | O32: {=SUM(L32:N32)/(J32*3)} -> 0 | R32: 1 | S32: Campeão
E33: Membros Superiores Puxada | F33: 5 | G33: ='Semana de Teste'!E12 -> Remada Inclinada ( Barbell Row ) | H33: 0.6 | I33: {=H33*'Semana de Teste'!$O$12} -> 0 | J33: 20 | K33: 0.0010416667 | O33: {=SUM(L33:N33)/(J33*3)} -> 0 | R33: 0.99 | S33: Competitivo
G34: ='Semana de Teste'!E13 -> Puxada Frontal ( Supinação ) | H34: 0.6 | I34: {=H34*'Semana de Teste'!$O$13} -> 0 | J34: 20 | K34: 0.0010416667 | O34: {=SUM(L34:N34)/(J34*3)} -> 0 | R34: 0.9
G35: ='Semana de Teste'!E14 -> Remada Inclinada com Halter | H35: 0.6 | I35: {=H35*'Semana de Teste'!$O$14} -> 0 | J35: 20 | K35: 0.0010416667 | O35: {=SUM(L35:N35)/(J35*3)} -> 0 | R35: 0.89 | S35: Pré-Competitivo
G36: ='Semana de Teste'!E15 -> Voador Inverso no banco inclinado com Halter | H36: 0.6 | I36: {=H36*'Semana de Teste'!$O$15} -> 0 | J36: 20 | K36: 0.0010416667 | O36: {=SUM(L36:N36)/(J36*3)} -> 0 | R36: 0.8
G37: ='Semana de Teste'!E16 -> Rosca Martelo com Halter | H37: 0.6 | I37: {=H37*'Semana de Teste'!$O$16} -> 0 | J37: 20 | K37: 0.0010416667 | O37: {=SUM(L37:N37)/(J37*3)} -> 0 | R37: 0.79 | S37: Em Evolução
E38: Membros Inferiores | F38: 6 | G38: ='Semana de Teste'!E17 -> Agachamento com Barra nas Costas (Back Squat) | H38: 0.6 | I38: {=H38*'Semana de Teste'!$O$17} -> 0 | J38: 20 | K38: 0.0010416667 | O38: {=SUM(L38:N38)/(J38*3)} -> 0 | R38: 0.7
G39: ='Semana de Teste'!E18 -> Levantamento Terra ( Deadlift) | H39: 0.6 | I39: {=H39*'Semana de Teste'!$O$18} -> 0 | J39: 20 | K39: 0.0010416667 | O39: {=SUM(L39:N39)/(J39*3)} -> 0 | R39: 0.69 | S39: Fraco
G40: ='Semana de Teste'!E19 -> Afundo com Halteres | H40: 0.6 | I40: {=H40*'Semana de Teste'!$O$19} -> 0 | J40: 20 | K40: 0.0010416667 | O40: {=SUM(L40:N40)/(J40*3)} -> 0 | R40: 0.6
G41: ='Semana de Teste'!E20 -> Stiff com Halter | H41: 0.6 | I41: {=H41*'Semana de Teste'!$O$20} -> 0 | J41: 20 | K41: 0.0010416667 | O41: {=SUM(L41:N41)/(J41*3)} -> 0 | R41: 0.59 | S41: Muito Fraco
...

Sheet Semana de Reteste
C2: RETESTE | W2: Segunda | X2: Terça | Y2: Quarta | Z2: Quinta | AA2: Sexta | AB2: Sábado | AC2: Domingo
W3: Empurrada | X3: Vo2 max | Y3: Descanso | Z3: Puxada | AA3: Perna | AB3: Aula | AC3: Descanso
C5: Treino | D5: N | E5: Exercício | F5: BUILD UP | I5: Confere ! | M5: Série 2 | P5: Série 3 | S5: 1 RM (Kg) | T5: 1RM (Kg) Inicial | U5: Melhora
F6: Carga (Kg) | G6: Repetições | H6: Descanso | I6: Teste | J6: Repetições | K6: Confere | L6: Descanso | M6: Carga (Kg) | N6: Repetições | O6: Descanso | P6: Carga (Kg) | Q6: Repetições | R6: Descanso
C7: Membros Superiores Empurrada | D7: 1 | E7: ='Semana de Teste'!E7 -> Supino Reto ( Bench Press ) | F7: =I7*80% -> 64 | G7: 5 a 7 | H7: ='Semana de Teste'!N7 -> 3 minutos | I7: ='Semana de Teste'!L7 -> 80 | J7: ='Semana de Teste'!M7 -> 4 | K7: 5 | L7: 3 minutos | M7: 105 | N7: 5 | O7: 3 minutos | P7: 108 | Q7: 3 | R7: 3 minutos | S7: =IF(Q7=1,P7,(Q7*P7*0.0333)+P7) -> 118.7892 | T7: ='Semana de Teste'!O7 -> 90.656 | U7: =IF(S7=0, 0,(S7-T7)/T7) -> 0.31032916
D8: 2 | E8: ='Semana de Teste'!E8 -> Supino Inclinado com Barra | F8: =I8*80% -> 0 | G8: 5 a 7 | H8: ='Semana de Teste'!N8 -> 3 minutos | I8: ='Semana de Teste'!L8 | J8: ='Semana de Teste'!M8 | L8: 3 minutos | O8: 3 minutos | R8: 3 minutos | S8: =IF(Q8=1,P8,(Q8*P8*0.0333)+P8) -> 0 | T8: ='Semana de Teste'!O8 -> 0 | U8: =IF(S8=0, 0,(S8-T8)/T8) -> 0
D9: 3 | E9: ='Semana de Teste'!E9 -> Dumbbell Shoulder Press | F9: =I9*80% -> 0 | G9: 5 a 7 | H9: ='Semana de Teste'!N9 -> 3 minutos | I9: ='Semana de Teste'!L9 | J9: ='Semana de Teste'!M9 | L9: 3 minutos | O9: 3 minutos | R9: 3 minutos | S9: =IF(Q9=1,P9,(Q9*P9*0.0333)+P9) -> 0 | T9: ='Semana de Teste'!O9 -> 0 | U9: =IF(S9=0, 0,(S9-T9)/T9) -> 0
D10: 4 | E10: ='Semana de Teste'!E10 -> Remada Alta com Barra | F10: =I10*80% -> 0 | G10: 5 a 7 | H10: ='Semana de Teste'!N10 -> 3 minutos | I10: ='Semana de Teste'!L10 | J10: ='Semana de Teste'!M10 | L10: 3 minutos | O10: 3 minutos | R10: 3 minutos | S10: =IF(Q10=1,P10,(Q10*P10*0.0333)+P10) -> 0 | T10: ='Semana de Teste'!O10 -> 0 | U10: =IF(S10=0, 0,(S10-T10)/T10) -> 0
D11: 5 | E11: ='Semana de Teste'!E11 -> Tríceps Pulley | F11: =I11*80% -> 0 | G11: 5 a 7 | H11: ='Semana de Teste'!N11 -> 3 minutos | I11: ='Semana de Teste'!L11 | J11: ='Semana de Teste'!M11 | L11: 3 minutos | O11: 3 minutos | R11: 3 minutos | S11: =IF(Q11=1,P11,(Q11*P11*0.0333)+P11) -> 0 | T11: ='Semana de Teste'!O11 -> 0 | U11: =IF(S11=0, 0,(S11-T11)/T11) -> 0
C12: Membros Superiores Puxada | D12: 1 | E12: ='Semana de Teste'!E12 -> Remada Inclinada ( Barbell Row ) | F12: =I12*80% -> 0 | G12: 5 a 7 | H12: ='Semana de Teste'!N12 -> 3 minutos | I12: ='Semana de Teste'!L12 | J12: ='Semana de Teste'!M12 | L12: 3 minutos | O12: 3 minutos | R12: 3 minutos | S12: =IF(Q12=1,P12,(Q12*P12*0.0333)+P12) -> 0 | T12: ='Semana de Teste'!O12 -> 0 | U12: =IF(S12=0, 0,(S12-T12)/T12) -> 0
D13: 2 | E13: ='Semana de Teste'!E13 -> Puxada Frontal ( Supinação ) | F13: =I13*80% -> 0 | G13: 5 a 7 | H13: ='Semana de Teste'!N13 -> 3 minutos | I13: ='Semana de Teste'!L13 | J13: ='Semana de Teste'!M13 | L13: 3 minutos | O13: 3 minutos | R13: 3 minutos | S13: =IF(Q13=1,P13,(Q13*P13*0.0333)+P13) -> 0 | T13: ='Semana de Teste'!O13 -> 0 | U13: =IF(S13=0, 0,(S13-T13)/T13) -> 0
D14: 3 | E14: ='Semana de Teste'!E14 -> Remada Inclinada com Halter | F14: =I14*80% -> 0 | G14: 5 a 7 | H14: ='Semana de Teste'!N14 -> 3 minutos | I14: ='Semana de Teste'!L14 | J14: ='Semana de Teste'!M14 | L14: 3 minutos | O14: 3 minutos | R14: 3 minutos | S14: =IF(Q14=1,P14,(Q14*P14*0.0333)+P14) -> 0 | T14: ='Semana de Teste'!O14 -> 0 | U14: =IF(S14=0, 0,(S14-T14)/T14) -> 0
D15: 4 | E15: ='Semana de Teste'!E15 -> Voador Inverso no banco inclinado com Halter | F15: =I15*80% -> 0 | G15: 5 a 7 | H15: ='Semana de Teste'!N15 -> 3 minutos | I15: ='Semana de Teste'!L15 | J15: ='Semana de Teste'!M15 | L15: 3 minutos | O15: 3 minutos | R15: 3 minutos | S15: =IF(Q15=1,P15,(Q15*P15*0.0333)+P15) -> 0 | T15: ='Semana de Teste'!O15 -> 0 | U15: =IF(S15=0, 0,(S15-T15)/T15) -> 0
D16: 5 | E16: ='Semana de Teste'!E16 -> Rosca Martelo com Halter | F16: =I16*80% -> 0 | G16: 5 a 7 | H16: ='Semana de Teste'!N16 -> 3 minutos | I16: ='Semana de Teste'!L16 | J16: ='Semana de Teste'!M16 | L16: 3 minutos | O16: 3 minutos | R16: 3 minutos | S16: =IF(Q16=1,P16,(Q16*P16*0.0333)+P16) -> 0 | T16: ='Semana de Teste'!O16 -> 0 | U16: =IF(S16=0, 0,(S16-T16)/T16) -> 0
C17: Membros Inferiores | D17: 1 | E17: ='Semana de Teste'!E17 -> Agachamento com Barra nas Costas (Back Squat) | F17: =I17*80% -> 0 | G17: 5 a 7 | H17: ='Semana de Teste'!N17 -> 3 minutos | I17: ='Semana de Teste'!L17 | J17: ='Semana de Teste'!M17 | L17: 3 minutos | O17: 3 minutos | R17: 3 minutos | S17: =IF(Q17=1,P17,(Q17*P17*0.0333)+P17) -> 0 | T17: ='Semana de Teste'!O17 -> 0 | U17: =IF(S17=0, 0,(S17-T17)/T17) -> 0
D18: 2 | E18: ='Semana de Teste'!E18 -> Levantamento Terra ( Deadlift) | F18: =I18*80% -> 0 | G18: 5 a 7 | H18: ='Semana de Teste'!N18 -> 3 minutos | I18: ='Semana de Teste'!L18 | J18: ='Semana de Teste'!M18 | L18: 3 minutos | O18: 3 minutos | R18: 3 minutos | S18: =IF(Q18=1,P18,(Q18*P18*0.0333)+P18) -> 0 | T18: ='Semana de Teste'!O18 -> 0 | U18: =IF(S18=0, 0,(S18-T18)/T18) -> 0
D19: 3 | E19: ='Semana de Teste'!E19 -> Afundo com Halteres | F19: =I19*80% -> 0 | G19: 5 a 7 | H19: ='Semana de Teste'!N19 -> 3 minutos | I19: ='Semana de Teste'!L19 | J19: ='Semana de Teste'!M19 | L19: 3 minutos | O19: 3 minutos | R19: 3 minutos | S19: =IF(Q19=1,P19,(Q19*P19*0.0333)+P19) -> 0 | T19: ='Semana de Teste'!O19 -> 0 | U19: =IF(S19=0, 0,(S19-T19)/T19) -> 0
D20: 4 | E20: ='Semana de Teste'!E20 -> Stiff com Halter | F20: =I20*80% -> 0 | G20: 5 a 7 | H20: ='Semana de Teste'!N20 -> 3 minutos | I20: ='Semana de Teste'!L20 | J20: ='Semana de Teste'!M20 | L20: 3 minutos | O20: 3 minutos | R20: 3 minutos | S20: =IF(Q20=1,P20,(Q20*P20*0.0333)+P20) -> 0 | T20: ='Semana de Teste'!O20 -> 0 | U20: =IF(S20=0, 0,(S20-T20)/T20) -> 0
B23: Assessment | C23: Date | D23: Distance ( meters) | E23: Vo2 Max (ml/kg/min) | F23: Vvo2 Max (Km/h) | G23: Improvement
B24: Old | C24: =Dashboard!D19 -> 46041 | D24: ='Semana de Teste'!D23 -> 2600 | E24: ='Semana de Teste'!D24 -> 46.679287 | F24: ='Semana de Teste'!D25 -> 13 | G24: =(F25-F24)/F24 -> -1
B25: New | C25: =Dashboard!E19 | E25: =((D25-504.1)/44.9) -> -11.227171 | F25: =((D25/ 12)*0.06) -> 0

Sheet Nutrição
A2: PRE TREINO | C2: Está Refeição deve ser Feita com 1 hora antes do treino
A3: Carboidratos (g) | B3: =Dashboard!D22 -> 80 | G3: Pré Treino
G4: Alimento | H4: Unidade | I4: Qantidade | J4: Carboidratos
A5: PÓS TREINO | G5: Pão francês | H5: =IFERROR(VLOOKUP(G5,'Tabela Nutri'!$G$3:$I$19,2, FALSE), "") -> Unidade | I5: 3 | J5: =IFERROR(VLOOKUP(G5,'Tabela Nutri'!$G$3:$I$19,3, FALSE)*I5, "0") -> 87
A6: Carboidratos (g) | B6: =IF(Dashboard!D22>Dashboard!J21,Dashboard!D22*0.8,Dashboard!D22) -> 64 | G6: Banana | H6: =IFERROR(VLOOKUP(G6,'Tabela Nutri'!$G$3:$I$19,2, FALSE), "") -> Unidade (75g) | I6: 1 | J6: =IFERROR(VLOOKUP(G6,'Tabela Nutri'!$G$3:$I$19,3, FALSE)*I6, "0") -> 16.5
A7: Proteína (g) | B7: =B6/4 -> 16 | G7: Mel | H7: =IFERROR(VLOOKUP(G7,'Tabela Nutri'!$G$3:$I$19,2, FALSE), "") -> Colher de Sopa (15g) | I7: 1 | J7: =IFERROR(VLOOKUP(G7,'Tabela Nutri'!$G$3:$I$19,3, FALSE)*I7, "0") -> 12
H8: =IFERROR(VLOOKUP(G8,'Tabela Nutri'!$G$3:$I$19,2, FALSE), "") | J8: =IFERROR(VLOOKUP(G8,'Tabela Nutri'!$G$3:$I$19,3, FALSE)*I8, "0") -> 0
H9: =IFERROR(VLOOKUP(G9,'Tabela Nutri'!$G$3:$I$19,2, FALSE), "") | J9: =IFERROR(VLOOKUP(G9,'Tabela Nutri'!$G$3:$I$19,3, FALSE)*I9, "0") -> 0
G10: ADEQUAÇÃO | I10: =IF(SUM(J5:J9) > B3*1.1, "Ultrapassou a Necessidade", IF(SUM(J5:J9) < B3*0.9, "Abaixo das Necessidades", "OK")) -> Ultrapassou a Necessidade
A11: DICA DE OURO
A12: ="A cada 3-4 horas voce deve consumir "&ROUND(Dashboard!D22*0.3,0)&"g de proteína" -> A cada 3-4 horas voce deve consumir 24g de proteína
G13: Pós Treino
A14: COMO ESCOLHER UM BOM WHEY | G14: Alimento | H14: Unidade | I14: Qantidade | J14: Carboidratos
A15: Em um porção de 30g deve conter no minimo 22g de proteínas e 2,2g de leucina. Além disso o carboidratos não pode passar de 6,5g. | G15: Macarrão cozido | H15: =IFERROR(VLOOKUP(G15,'Tabela Nutri'!$G$3:$I$19,2, FALSE), "") -> Porção de 100g | I15: 1 | J15: =IFERROR(VLOOKUP(G15,'Tabela Nutri'!$G$3:$I$19,3, FALSE)*I15, "0") -> 25
G16: Maçã | H16: =IFERROR(VLOOKUP(G16,'Tabela Nutri'!$G$3:$I$19,2, FALSE), "") -> Unidade | I16: 2 | J16: =IFERROR(VLOOKUP(G16,'Tabela Nutri'!$G$3:$I$19,3, FALSE)*I16, "0") -> 40
G17: Pão francês | H17: =IFERROR(VLOOKUP(G17,'Tabela Nutri'!$G$3:$I$19,2, FALSE), "") -> Unidade | I17: 0 | J17: =IFERROR(VLOOKUP(G17,'Tabela Nutri'!$G$3:$I$19,3, FALSE)*I17, "0") -> 0
H18: =IFERROR(VLOOKUP(G18,'Tabela Nutri'!$G$3:$I$19,2, FALSE), "") | J18: =IFERROR(VLOOKUP(G18,'Tabela Nutri'!$G$3:$I$19,3, FALSE)*I18, "0") -> 0
H19: =IFERROR(VLOOKUP(G19,'Tabela Nutri'!$G$3:$I$19,2, FALSE), "") | J19: =IFERROR(VLOOKUP(G19,'Tabela Nutri'!$G$3:$I$19,3, FALSE)*I19, "0") -> 0
G20: Whey Protein | H20: 1 | J20: =(B7*30)/22 -> 21.818182
G21: ADEQUAÇÃO | I21: =IF(SUM(J15:J19) > B6*1.1, "Ultrapassou a Necessidade", IF(SUM(J15:J19) < B6*0.9, "Abaixo das Necessidades", "OK")) -> OK

Sheet Tabelas
V23: TABELA DE EXERCICIOS - caso queiro moficicar usar essa.
V26: Pull | W26: 1 | X26: Remada Inclinada ( Barbell Row )
W27: 2 | X27: Lat Pull Down | Y27: Puxada Frontal ( Supinação ) | Z27: Puxada Frontal ( Triangulo )
W28: 3 | X28: Remada Inclinada com Halter | Y28: Remada Baixa | Z28: Remada Sentada na Máquina
W29: 4 | X29: Voador Inverso no banco inclinado com Halter | Y29: Voador Inverso na Maquina | Z29: Crossover na Polia Alta
W30: 5 | X30: Rosca Martelo com Halter | Y30: Rosca Direta com Barra W | Z30: Rosca na Máquina (Scott)
V32: Push | W32: 1 | X32: Supino Reto ( Bench Press )
W33: 2 | X33: Supino Inclinado com Halteres | Y33: Supino Inclinado com Barra | Z33: Supino Inclinado na Máquina
W34: 3 | X34: Dumbbell Shoulder Press | Y34: Desenvolvimento com Barra ( Shoulder Press ) | Z34: Shoulder Press na Máquina
W35: 4 | X35: Dumbbell Evelação Lateral | Y35: Elevação Lateral Inclinada com Halter | Z35: Remada Alta com Barra
W36: 5 | X36: Tríceps Pulley | Y36: Tríceps Francês com Halter | Z36: Tríceps Testa com Barra
V38: Lower Body | W38: 1 | X38: Agachamento com Barra nas Costas (Back Squat)
W39: 2 | X39: Levantamento Terra ( Deadlift)
W40: 3 | X40: Búlgaro com Halter | Y40: Afundo com Halteres | Z40: Afundo Smith
W41: 4 | X41: Stiff com Halter | Y41: Stiff com Barra | Z41: Flexora de Joelho Sentada
W46: 1 | X46: Remada Inclinada ( Barbell Row )
W47: 2 | X47: Lat Pull Down
W48: 3 | X48: Puxada Frontal ( Supinação )
W49: 4 | X49: Puxada Frontal ( Triangulo )
W50: 5 | X50: Remada Inclinada com Halter
W51: 6 | X51: Remada Baixa
W52: 7 | X52: Remada Sentada na Máquina
W53: 8 | X53: Voador Inverso no banco inclinado com Halter
W54: 9 | X54: Voador Inverso na Maquina
W55: 10 | X55: Crossover na Polia Alta
W56: 11 | X56: Rosca Martelo com Halter
W57: 12 | X57: Rosca Direta com Barra W
... W81: 34 | X81: Flexora de Joelho Sentada

Sheet Videos
A1: 1 | B1: Remada Inclinada ( Barbell Row )
A2: 2 | B2: Lat Pull Down
A3: 3 | B3: Puxada Frontal ( Supinação )
A4: 4 | B4: Puxada Frontal ( Triangulo )
A5: 5 | B5: Remada Inclinada com Halter
A6: 6 | B6: Remada Baixa
A7: 7 | B7: Remada Sentada na Máquina
A8: 8 | B8: Voador Inverso no banco inclinado com Halter
A9: 9 | B9: Voador Inverso na Maquina
A10: 10 | B10: Crossover na Polia Alta
A11: 11 | B11: Rosca Martelo com Halter
A12: 12 | B12: Rosca Direta com Barra W
... A36: 34 | B36: Flexora de Joelho Sentada

Sheet Tabela Nutri
A2: Alimento | B2: Carboidratos (g) | C2: Proteína (g) | G2: Alimento | H2: UNidade de Medida | I2: Quantidade de Carboidrato
A3: Arroz branco cozido | B3: 28 | C3: 2.5 | G3: Arroz branco cozido | H3: Colher de Sopa (20g) | I3: 5
A4: Arroz integral cozido | B4: 25 | C4: 2.6 | G4: Arroz integral cozido | H4: Colher de Sopa (20g) | I4: 5
A5: Macarrão cozido | B5: 25 | C5: 4 | G5: Macarrão cozido | H5: Porção de 100g | I5: 25
A6: Pão francês | B6: 55 | C6: 8 | G6: Pão francês | H6: Unidade | I6: 29
A7: Mel | B7: 80 | C7: 9 | G7: Mel | H7: Colher de Sopa (15g) | I7: 12
A8: Aveia em flocos | B8: 66 | C8: 17 | G8: Aveia em flocos | H8: Colher de Sopa (15g) | I8: 10
A9: Tapioca (goma) | B9: 86 | C9: 0.2 | G9: Tapioca (goma) | H9: Colher de Sopa (15g) | I9: 12
A10: Batata cozida | B10: 20 | C10: 2 | G10: Batata cozida | H10: Porção de 100g | I10: 20
A11: Batata-doce cozida | B11: 18 | C11: 1.3 | G11: Batata-doce cozida | H11: Porção de 100g | I11: 18
A12: Inhame cozido | B12: 27 | C12: 1.5 | G12: Inhame cozido | H12: Porção de 100g | I12: 27
A13: Mandioca cozida | B13: 30 | C13: 1 | G13: Mandioca cozida | H13: Porção de 100g | I13: 30
A14: Maçã | B14: 14 | C14: 0.3 | G14: Maçã | H14: Unidade | I14: 20
... A17: Mamão | B17: 10 | C17: 0.5 | G17: Mamão | H17: Fatia (200g) | I17: 17
A18: Banana | B18: 22 | C18: 0 | G18: Banana | H18: Unidade (75g) | I18: =(75*B18)/100 -> 16.5
G19: Geleia De Fruta | H19: Ponta de Faca (5g)
